Traceback (most recent call last):
  File "/Users/zehiu/PycharmProjects/DeepLearning/dnd_music/training.py", line 110, in <module>
    main()
  File "/Users/zehiu/PycharmProjects/DeepLearning/dnd_music/training.py", line 106, in main
    train_model()
  File "/Users/zehiu/PycharmProjects/DeepLearning/dnd_music/training.py", line 70, in train_model
    loss = diffusion_loss(model, images, t, noise, diffusion)
           ^^^^^^^^^^^^^^^^^^^^^^^^^^^^^^^^^^^^^^^^^^^^^^^^^^
  File "/Users/zehiu/PycharmProjects/DeepLearning/dnd_music/training.py", line 31, in diffusion_loss
    predicted_noise = model(x_t, t)
                      ^^^^^^^^^^^^^
  File "/Users/zehiu/anaconda3/lib/python3.11/site-packages/torch/nn/modules/module.py", line 1518, in _wrapped_call_impl
    return self._call_impl(*args, **kwargs)
           ^^^^^^^^^^^^^^^^^^^^^^^^^^^^^^^^
  File "/Users/zehiu/anaconda3/lib/python3.11/site-packages/torch/nn/modules/module.py", line 1527, in _call_impl
    return forward_call(*args, **kwargs)
           ^^^^^^^^^^^^^^^^^^^^^^^^^^^^^
  File "/Users/zehiu/PycharmProjects/DeepLearning/dnd_music/model.py", line 74, in forward
    enc1 = self.enc1(x)
           ^^^^^^^^^
  File "/Users/zehiu/anaconda3/lib/python3.11/site-packages/torch/nn/modules/module.py", line 1695, in __getattr__
    raise AttributeError(f"'{type(self).__name__}' object has no attribute '{name}'")
AttributeError: 'UNet' object has no attribute 'enc1'